Workbook

Sheet INDICE_H
A1: NOMBRE MÓDULO | B1: DESCRIPCIÓN | C1: NOMBRE DE HISTORIA DE USUARIOS | D1: NÚMERO HISTORIA | E1: LINK | F1: Definición release 1
A2: 0. NUEVO SISTEMA DE GESTIÓN DE ANEXOS | B2: 1. Módulos del sistema | C2: Historia de usuario : Nuevo sistema de Anexos Intranet | D2: H001 | E2: =+HYPERLINK("#'1_Release'!C" &MATCH(D2,'1_Release'!C:C,0),D2) -> H001 | F2: SI
B3: 2. Compatibilidad de navegadores y sistemas | C3: Historia de usuario : Compatibilidad de navegadores y sistemas | D3: H003 | E3: =+HYPERLINK("#'1_Release'!C" &MATCH(D3,'1_Release'!C:C,0),D3) -> H003 | F3: SI
B4: 3. Creación de roles | C4: Historia de usuario : Creación de roles | D4: H004 | E4: =+HYPERLINK("#'1_Release'!C" &MATCH(D4,'1_Release'!C:C,0),D4) -> H004 | F4: SI
B5: 4. Funcionalidades Génericas | C5: Historia de usuario : Funcionalidades genéricas | D5: H006 | E5: =+HYPERLINK("#'1_Release'!C" &MATCH(D5,'1_Release'!C:C,0),D5) -> H006 | F5: SI
C6: Historia de usuario : El sistema debe contar con una funcionalidad que permita parametrizar los mensajes del sistema tanto en alertas como controles. | D6: H082 | E6: =+HYPERLINK("#'1_Release'!C" &MATCH(D6,'1_Release'!C:C,0),D6) -> H082 | F6: SI
C7: Historia de usuario : Funcionales – Búsqueda de Elementos en Diseñador de Anexos | D7: H092 | E7: =+HYPERLINK("#'1_Release'!C" &MATCH(D7,'1_Release'!C:C,0),D7) -> H092 | F7: SI
A9: NOMBRE MÓDULO | B9: DESCRIPCIÓN | C9: NOMBRE DE HISTORIA DE USUARIOS | D9: NÚMERO HISTORIA | E9: LINK | F9: Definición release 1
A10: 1. MÓDULO ADMINISTRATIVO | B10: 1. Crear la estructura del anexo | C10: Historia de usuario : Administrar las estructuras de los Anexos | D10: H071 | E10: =+HYPERLINK("#'1_Release'!C" &MATCH(D10,'1_Release'!C:C,0),D10) -> H071 | F10: SI
C11: Historia de usuario : Estructura del diseñador del Nuevo Sistema de Gestión de Anexos | D11: H005 | E11: =+HYPERLINK("#'1_Release'!C" &MATCH(D11,'1_Release'!C:C,0),D11) -> H005 | F11: SI
B12: 2. Incluir campos configurables | C12: Historia de usuario : Creación, actualización o inactivación de conceptos - casilleros de información | D12: H007 | E12: =+HYPERLINK("#'1_Release'!C" &MATCH(D12,'1_Release'!C:C,0),D12) -> H007 | F12: SI
C13: Historia de usuario : Implementación de Fórmulas en el Diseñador de Anexos Tributarios | D13: H018 | E13: =+HYPERLINK("#'1_Release'!C" &MATCH(D13,'1_Release'!C:C,0),D13) -> H018 | F13: SI
B14: 3. Incluir niveles y subniveles | C14: Historia de usuario : Creación de niveles - subniveles | D14: H008 | E14: =+HYPERLINK("#'1_Release'!C" &MATCH(D14,'1_Release'!C:C,0),D14) -> H008 | F14: si
B15: 4. Incluir secciones | C15: Historia de usuario : Previsualizar el anexo con su estructura | D15: H009 | E15: =+HYPERLINK("#'1_Release'!C" &MATCH(D15,'1_Release'!C:C,0),D15) -> H009 | F15: si
C16: Historia de usuario : Funcionalidad de expandir o extraer en secciones | D16: H081 | E16: =+HYPERLINK("#'1_Release'!C" &MATCH(D16,'1_Release'!C:C,0),D16) -> H081 | F16: si
C17: Historia de usuario : Crear secciones / Unidades de información | D17: H010 | E17: =+HYPERLINK("#'1_Release'!C" &MATCH(D17,'1_Release'!C:C,0),D17) -> H010 | F17: si
C18: Historia de usuario : Editar secciones | D18: H014 | E18: =+HYPERLINK("#'1_Release'!C" &MATCH(D18,'1_Release'!C:C,0),D18) -> H014 | F18: si
C19: Historia de usuario : Eliminar o inactivar secciones | D19: H012 | E19: =+HYPERLINK("#'1_Release'!C" &MATCH(D19,'1_Release'!C:C,0),D19) -> H012 | F19: si
C20: Historia de usuario : Personalizar secciones | D20: H011 | E20: =+HYPERLINK("#'1_Release'!C" &MATCH(D20,'1_Release'!C:C,0),D20) -> H011 | F20: si
C21: Historia de usuario : Reordenar secciones | D21: H013 | E21: =+HYPERLINK("#'1_Release'!C" &MATCH(D21,'1_Release'!C:C,0),D21) -> H013 | F21: si
B22: 5. Crear estados del anexo y flujo de aprobación en la etapa de diseño | C22: Historia de usuario : Creación del módulo de aprobación | D22: H075 | E22: =+HYPERLINK("#'1_Release'!C" &MATCH(D22,'1_Release'!C:C,0),D22) -> H075 | F22: SI
C23: Historia de usuario : Estados de los anexos en su etapa de diseño. | D23: H019 | E23: =+HYPERLINK("#'1_Release'!C" &MATCH(D23,'1_Release'!C:C,0),D23) -> H019 | F23: SI
C24: Historia de usuario : Flujo de aprobación | D24: H072 | E24: =+HYPERLINK("#'1_Release'!C" &MATCH(D24,'1_Release'!C:C,0),D24) -> H072 | F24: SI
B25: 6. Incluir catálogos | C25: Historia de usuario : Administración de catálogos específicos | D25: H020 | E25: =+HYPERLINK("#'1_Release'!C" &MATCH(D25,'1_Release'!C:C,0),D25) -> H020 | F25: SI
C26: Historia de usuario : Obtener información de catálogos para relación con casilleros y catálogos | D26: H022 | E26: =+HYPERLINK("#'1_Release'!C" &MATCH(D26,'1_Release'!C:C,0),D26) -> H022 | F26: SI
C27: Historia de usuario : Relacionar catálogos específicos por anexo | D27: H021 | E27: =+HYPERLINK("#'1_Release'!C" &MATCH(D27,'1_Release'!C:C,0),D27) -> H021 | F27: SI
B28: 7. Configurar canales de recepción | C28: Historia de usuario : Parametrización de mecanismos de recepción de información | D28: H029 | E28: =+HYPERLINK("#'1_Release'!C" &MATCH(D28,'1_Release'!C:C,0),D28) -> H029 | F28: SI
B29: 9. Reglas de Proceso | C29: Historia de usuario : Dependencia de niveles - subniveles de casilleros. | D29: H025 | E29: =+HYPERLINK("#'1_Release'!C" &MATCH(D29,'1_Release'!C:C,0),D29) -> H025 | F29: SI
C30: Historia de usuario : Mecanismo de validaciones para el Sistema de Gestion de Anexos. | D30: H025A | E30: =+HYPERLINK("#'1_Release'!C" &MATCH(D30,'1_Release'!C:C,0),D30) -> H025A | F30: SI
C31: Historia de usuario : Parametrización de los datos y sus servicios en el Sistema de Gestion de Anexos. | D31: H024 | E31: =+HYPERLINK("#'1_Release'!C" &MATCH(D31,'1_Release'!C:C,0),D31) -> H024
B32: 9.1. Identificadores únicos (Primary Key) | C32: Historia de usuario : Primary key | D32: H017 | E32: =+HYPERLINK("#'1_Release'!C" &MATCH(D32,'1_Release'!C:C,0),D32) -> H017 | F32: SI
B33: 9.5. Pistas de Auditoría | C33: Historia de usuario : Implementación de Pistas de auditoria | D33: H033 | E33: =+HYPERLINK("#'1_Release'!C" &MATCH(D33,'1_Release'!C:C,0),D33) -> H033 | F33: SI
B35: DESCRIPCIÓN | C35: NOMBRE DE HISTORIA DE USUARIOS | D35: NÚMERO HISTORIA | E35: LINK | F35: Definición release 1
B36: 2. Se contempla integración con Catastro Tributario para obtener la información de las características y atributos de los contribuyentes. | C36: Historia de usuario : Catastro | D36: H067 | E36: =+HYPERLINK("#'1_Release'!C" &MATCH(D36,'1_Release'!C:C,0),D36) -> H067 | F36: SI
B37: 6. Se contempla integración con Alertas y Avisos | C37: Historia de usuario : Alertas y Avisos | D37: H054 | E37: =+HYPERLINK("#'1_Release'!C" &MATCH(D37,'1_Release'!C:C,0),D37) -> H054 | F37: SI
C38: Historia de usuario : Notificar publicación anexo | D38: H098 | E38: =+HYPERLINK("#'1_Release'!C" &MATCH(D38,'1_Release'!C:C,0),D38) -> H098 | F38: SI
C39: Historia de usuario : Notificar solicitud revisión : | D39: H099 | E39: =+HYPERLINK("#'1_Release'!C" &MATCH(D39,'1_Release'!C:C,0),D39) -> H099 | F39: SI
B40: 7. Se contempla integración con Gestor de Obligaciones | C40: Historia de usuario : Gestor de Obligaciones | D40: H055 | E40: =+HYPERLINK("#'1_Release'!C" &MATCH(D40,'1_Release'!C:C,0),D40) -> H055 | F40: SI
B41: 9.3. Se contempla integración con PISTAS DE AUDITORIA | C41: Historia de usuario : Pistas de Auditoría | D41: H060 | E41: =+HYPERLINK("#'1_Release'!C" &MATCH(D41,'1_Release'!C:C,0),D41) -> H060 | F41: SI
C42: Historia de usuario : Pistas de Auditoría funcionalidades críticas / Consulta de Archivo cargado | D42: H097 | E42: =+HYPERLINK("#'1_Release'!C" &MATCH(D42,'1_Release'!C:C,0),D42) -> H097 | F42: SI
...

Sheet 1_Release
B1: NUEVO SISTEMA DE GESTIÓN DE ANEXOS
B2: DESCRIPCIÓN | C2: NÚMERO HISTORIA | D2: NOMBRE DE LA HISTORIA | E2: DESCRIPCIÓN HISTORIA | F2: CRITERIOS DE ACEPTACIÓN | G2: REF HISTORIA
B3: Módulos del sistema | C3: H001 | D3: Nuevo sistema de Anexos Intranet | E3: Como administrador Quiero crear un nuevo sistema de anexos en intranet que permita: el diseño y parametrización de nuevos anexos, la recepción de la información desde la página web, o recepción de archivos en distintos canales, y obtener información con los reportes para la toma de decisiones | F3: Criterios de aceptación 1:
F4: Requiero contar con un MÓDULO ADMINISTRATIVO que contenga la opción de Diseño / Configuraciones, para elaborar e implementar anexos, con sus respectivas parametrizaciones:
F5: Las opciones debe permitir entre otras, las siguientes funcionalidades:
F6: Diseño de Anexos
F7: Administrar la estructura de los anexos
F8: Creación de casilleros del anexo
F9: Creación de Catálogos de Anexos
F10: Relacionar Catálogos con uno o más Anexos
F11: Creación de secciones
F12: Administración de Usuarios
F13: Creación de niveles y subniveles
F14: Canales de recepción
F15: Parametrizaciones y Validaciones
F16: Búsqueda del listado de Anexos (Permite filtros por estado) con acciones para creación, modificación y actualización por cada anexo
B22: Compatibilidad de navegadores y sistemas | C22: H003 | D22: Compatibilidad de navegadores y sistemas | E22: Como administrador quiero que la plataforma en internet sea compatible con navegadores Safari, Mozilla y Chrome (y sistemas operativos) para el correcto funcionamiento del aplicativo en diversos dispositivos. | F22: Criterios de aceptación 1:
F23: El sistema en internet debe funcionar en (diversos) navegadores como, por ejemplo: (Safari, Mozilla y Chrome)
F24: El sistema debe funcionar adecuadamente en diversos dispositivos como, por ejemplo: (laptops – tablets – celulares)
F25: El sistema debe ser responsive
B26: Creación de roles | C26: H004 | D26: Creación de roles | E26: Como dueño del sistema Quiero definir los accesos y funcionalidades que tendrán los roles del nuevo sistema para garantizar al acceso debido y oportuno de los servidores a nivel nacional. | F26: Criterios de aceptación 1:
F27: Requiero contar con un "Rol de Administrador" que permita al usuario administrador del sistema realizar la configuración y diseño de nuevos anexos o actualización de anexos elaborados con la nueva herramienta.
F28: Requiero contar con un "Rol de Supervisor" para la aprobación del diseño del anexo.
F29: Requiero contar con una funcionalidad que permita seleccionar los grupos de obligaciones (anexos) que serán asignados a una opción de una lista de los usuarios del proceso de Declaraciones y Anexos para la implementación y/o actualización de los anexos.
F30: Entre otros
B31: Funcionalidades genéricas | C31: H006 | D31: Funcionalidades genéricas | E31: Como administrador del sistema Quiero contar con funcionalidades generales para agilitar el flujo de elaboración del anexo para su implementación | F31: Criterios de aceptación 1:
F32: Las pantallas en las cuales el usuario administrador deba configurar las distintas funcionalidades deben contar con opciones para ACEPTAR o CANCELAR lo registrado.
F33: En caso de CANCELAR los registros, el sistema borra la información.
F34: En caso de ACEPTAR, los registros quedan guardados en el sistema y bases que correspondan.
F35: Las pantallas en las cuales el usuario administrador parametrice elementos como: conceptos, casilleros, tablas específicas, secciones y otros elementos de configuración según corresponda.
F36: Debe contar con opciones para AGREGAR, ACTUALIZAR o EDITAR y ELIMINAR los registros de dicha pantalla.
F37: Las acciones que realice el usuario administrador para ACTUALIZAR o ELIMINAR registros, debe contar con la funcionalidad que permita generar un mensaje de advertencia en una ventana emergente con las opciones ACEPTAR o CANCELAR (El mensaje será proporcionado funcionalmente de acuerdo con el contexto de cada pantalla). De manera general, al ejecutar la acción "ELIMINAR" debe presentar el mensaje, en caso de usar el botón "ACEPTAR" se ejecuta la acción seleccionada. En caso de "CANCELAR" los registros se mantienen como fueron creados.
F38: En el flujo de aprobación de anexos, no se puede enviar al flujo de aprobación mientras el anexo contenga errores.
F39: El sistema debe contar con una funcionalidad que permita parametrizar los mensajes del sistema que se presenten en alertas u otro tipo de controles
F40: El sistema debe contar con una funcionalidad que permita parametrizar notificaciones, para usuarios internos y externos mediante el uso de sistemas actuales o nuevos.
F41: Se requiere una funcionalidad que permita realizar búsquedas de ciertos elementos del anexo como por ejemplo búsqueda de conceptos, catálogos entre otros.
F42: Se requiere una funcionalidad que permita realizar búsquedas de ciertos elementos del anexo como por ejemplo búsqueda de conceptos, catálogos entre otros.
F43: Se requiere mostrar la información mediante pantallas, el sistema debe permitir configurar el número de filas que deben mostrarse por página al ejecutar algún tipo de consulta. Debe visualizar de acuerdo con el parámetro "Registros presentados por búsqueda. (ejemplo: búsqueda que se presente 50 registros por página en la búsqueda de los Anexos)
C44: H082 | D44: Historia de usuario: El sistema debe contar con una funcionalidad que permita parametrizar los mensajes del sistema tanto en alertas como controles. | E44: Como administrador del sistema, quiero poder definir mensajes de alerta específicos para cada tipo de configuración del sistema y advertir a otros administradores sobre posibles impactos o riesgos antes de aplicar cambios. | F44: Criterio de aceptación 1
F45: El sistema debe permitir asociar un mensaje de advertencia a cada parámetro configurable.
...

Sheet Notas
A1: Siempre
